===> Training mode

  0%|          | 0/21150 [00:00<?, ?it/s]Exception ignored in: <function _MultiProcessingDataLoaderIter.__del__ at 0x7f6c69cfde60>
Traceback (most recent call last):
  File "/home/alrawis/miniconda3/envs/ein/lib/python3.7/site-packages/torch/utils/data/dataloader.py", line 1101, in __del__
    self._shutdown_workers()
  File "/home/alrawis/miniconda3/envs/ein/lib/python3.7/site-packages/torch/utils/data/dataloader.py", line 1075, in _shutdown_workers
    w.join(timeout=_utils.MP_STATUS_CHECK_INTERVAL)
  File "/home/alrawis/miniconda3/envs/ein/lib/python3.7/multiprocessing/process.py", line 140, in join
    res = self._popen.wait(timeout)
  File "/home/alrawis/miniconda3/envs/ein/lib/python3.7/multiprocessing/popen_fork.py", line 45, in wait
    if not wait([self.sentinel], timeout):
  File "/home/alrawis/miniconda3/envs/ein/lib/python3.7/multiprocessing/connection.py", line 921, in wait
    ready = selector.select(timeout)
  File "/home/alrawis/miniconda3/envs/ein/lib/python3.7/selectors.py", line 415, in select
    fd_event_list = self._selector.poll(timeout)
  File "/home/alrawis/miniconda3/envs/ein/lib/python3.7/site-packages/torch/utils/data/_utils/signal_handling.py", line 66, in handler
    _error_if_any_worker_fails()
RuntimeError: DataLoader worker (pid 10022) exited unexpectedly with exit code 1. Details are lost due to multiprocessing. Rerunning with num_workers=0 may give better error trace.
  0%|          | 0/21150 [07:52<?, ?it/s]
Traceback (most recent call last):
  File "/home/alrawis/EIN-SELD/seld/main.py", line 80, in <module>
    sys.exit(main(args, cfg))
  File "/home/alrawis/EIN-SELD/seld/main.py", line 46, in main
    train.train(cfg, **train_initializer)
  File "/home/alrawis/EIN-SELD/seld/learning/train.py", line 52, in train
    epoch_it=epoch_it
  File "/home/alrawis/EIN-SELD/seld/methods/ein_seld/training.py", line 117, in validate_step
    batch_x = batch_x.cuda(non_blocking=True)
KeyboardInterrupt
